[2023-06-09T16:21:36.905+0000] {taskinstance.py:1103} INFO - Dependencies all met for dep_context=non-requeueable deps ti=<TaskInstance: first_dag.first_task scheduled__2023-05-31T00:00:00+00:00 [queued]>
[2023-06-09T16:21:36.921+0000] {taskinstance.py:1103} INFO - Dependencies all met for dep_context=requeueable deps ti=<TaskInstance: first_dag.first_task scheduled__2023-05-31T00:00:00+00:00 [queued]>
[2023-06-09T16:21:36.921+0000] {taskinstance.py:1308} INFO - Starting attempt 5 of 6
[2023-06-09T16:21:36.949+0000] {taskinstance.py:1327} INFO - Executing <Task(BashOperator): first_task> on 2023-05-31 00:00:00+00:00
[2023-06-09T16:21:36.957+0000] {standard_task_runner.py:57} INFO - Started process 2520 to run task
[2023-06-09T16:21:36.983+0000] {standard_task_runner.py:84} INFO - Running: ['***', 'tasks', 'run', 'first_dag', 'first_task', 'scheduled__2023-05-31T00:00:00+00:00', '--job-id', '176', '--raw', '--subdir', 'DAGS_FOLDER/first_dag.py', '--cfg-path', '/tmp/tmpb486ukgs']
[2023-06-09T16:21:36.988+0000] {standard_task_runner.py:85} INFO - Job 176: Subtask first_task
[2023-06-09T16:21:37.205+0000] {task_command.py:410} INFO - Running <TaskInstance: first_dag.first_task scheduled__2023-05-31T00:00:00+00:00 [running]> on host 93a4f35889be
[2023-06-09T16:21:37.749+0000] {taskinstance.py:1547} INFO - Exporting env vars: AIRFLOW_CTX_DAG_OWNER='madhu' AIRFLOW_CTX_DAG_ID='first_dag' AIRFLOW_CTX_TASK_ID='first_task' AIRFLOW_CTX_EXECUTION_DATE='2023-05-31T00:00:00+00:00' AIRFLOW_CTX_TRY_NUMBER='5' AIRFLOW_CTX_DAG_RUN_ID='scheduled__2023-05-31T00:00:00+00:00'
[2023-06-09T16:21:37.751+0000] {subprocess.py:63} INFO - Tmp dir root location: 
 /tmp
[2023-06-09T16:21:37.752+0000] {subprocess.py:75} INFO - Running command: ['/bin/bash', '-c', 'hello world i am madhu']
[2023-06-09T16:21:37.791+0000] {subprocess.py:86} INFO - Output:
[2023-06-09T16:21:37.796+0000] {subprocess.py:93} INFO - /bin/bash: line 1: hello: command not found
[2023-06-09T16:21:37.797+0000] {subprocess.py:97} INFO - Command exited with return code 127
[2023-06-09T16:21:37.845+0000] {taskinstance.py:1824} ERROR - Task failed with exception
Traceback (most recent call last):
  File "/home/airflow/.local/lib/python3.7/site-packages/airflow/operators/bash.py", line 211, in execute
    f"Bash command failed. The command returned a non-zero exit code {result.exit_code}."
airflow.exceptions.AirflowException: Bash command failed. The command returned a non-zero exit code 127.
[2023-06-09T16:21:37.869+0000] {taskinstance.py:1350} INFO - Marking task as UP_FOR_RETRY. dag_id=first_dag, task_id=first_task, execution_date=20230531T000000, start_date=20230609T162136, end_date=20230609T162137
[2023-06-09T16:21:37.957+0000] {standard_task_runner.py:109} ERROR - Failed to execute job 176 for task first_task (Bash command failed. The command returned a non-zero exit code 127.; 2520)
[2023-06-09T16:21:38.027+0000] {local_task_job_runner.py:225} INFO - Task exited with return code 1
[2023-06-09T16:21:38.125+0000] {taskinstance.py:2651} INFO - 0 downstream tasks scheduled from follow-on schedule check
