[2023-06-09T16:10:53.725+0000] {taskinstance.py:1103} INFO - Dependencies all met for dep_context=non-requeueable deps ti=<TaskInstance: first_dag.first_task scheduled__2023-05-11T00:00:00+00:00 [queued]>
[2023-06-09T16:10:53.747+0000] {taskinstance.py:1103} INFO - Dependencies all met for dep_context=requeueable deps ti=<TaskInstance: first_dag.first_task scheduled__2023-05-11T00:00:00+00:00 [queued]>
[2023-06-09T16:10:53.747+0000] {taskinstance.py:1308} INFO - Starting attempt 1 of 6
[2023-06-09T16:10:54.139+0000] {taskinstance.py:1327} INFO - Executing <Task(BashOperator): first_task> on 2023-05-11 00:00:00+00:00
[2023-06-09T16:10:54.167+0000] {standard_task_runner.py:57} INFO - Started process 1768 to run task
[2023-06-09T16:10:54.197+0000] {standard_task_runner.py:84} INFO - Running: ['***', 'tasks', 'run', 'first_dag', 'first_task', 'scheduled__2023-05-11T00:00:00+00:00', '--job-id', '5', '--raw', '--subdir', 'DAGS_FOLDER/first_dag.py', '--cfg-path', '/tmp/tmp1zki5ocw']
[2023-06-09T16:10:54.210+0000] {standard_task_runner.py:85} INFO - Job 5: Subtask first_task
[2023-06-09T16:10:55.039+0000] {task_command.py:410} INFO - Running <TaskInstance: first_dag.first_task scheduled__2023-05-11T00:00:00+00:00 [running]> on host 93a4f35889be
[2023-06-09T16:10:57.082+0000] {taskinstance.py:1547} INFO - Exporting env vars: AIRFLOW_CTX_DAG_OWNER='madhu' AIRFLOW_CTX_DAG_ID='first_dag' AIRFLOW_CTX_TASK_ID='first_task' AIRFLOW_CTX_EXECUTION_DATE='2023-05-11T00:00:00+00:00' AIRFLOW_CTX_TRY_NUMBER='1' AIRFLOW_CTX_DAG_RUN_ID='scheduled__2023-05-11T00:00:00+00:00'
[2023-06-09T16:10:57.129+0000] {subprocess.py:63} INFO - Tmp dir root location: 
 /tmp
[2023-06-09T16:10:57.206+0000] {subprocess.py:75} INFO - Running command: ['/bin/bash', '-c', 'hello world i am madhu']
[2023-06-09T16:10:58.276+0000] {subprocess.py:86} INFO - Output:
[2023-06-09T16:11:00.434+0000] {subprocess.py:93} INFO - /bin/bash: line 1: hello: command not found
[2023-06-09T16:11:00.474+0000] {subprocess.py:97} INFO - Command exited with return code 127
[2023-06-09T16:11:00.915+0000] {taskinstance.py:1824} ERROR - Task failed with exception
Traceback (most recent call last):
  File "/home/airflow/.local/lib/python3.7/site-packages/airflow/operators/bash.py", line 211, in execute
    f"Bash command failed. The command returned a non-zero exit code {result.exit_code}."
airflow.exceptions.AirflowException: Bash command failed. The command returned a non-zero exit code 127.
[2023-06-09T16:11:01.095+0000] {taskinstance.py:1350} INFO - Marking task as UP_FOR_RETRY. dag_id=first_dag, task_id=first_task, execution_date=20230511T000000, start_date=20230609T161053, end_date=20230609T161101
[2023-06-09T16:11:02.002+0000] {standard_task_runner.py:109} ERROR - Failed to execute job 5 for task first_task (Bash command failed. The command returned a non-zero exit code 127.; 1768)
[2023-06-09T16:11:02.250+0000] {local_task_job_runner.py:225} INFO - Task exited with return code 1
[2023-06-09T16:11:08.339+0000] {taskinstance.py:2651} INFO - 0 downstream tasks scheduled from follow-on schedule check
