[2023-06-09T16:13:08.730+0000] {taskinstance.py:1103} INFO - Dependencies all met for dep_context=non-requeueable deps ti=<TaskInstance: first_dag.first_task scheduled__2023-05-11T00:00:00+00:00 [queued]>
[2023-06-09T16:13:08.752+0000] {taskinstance.py:1103} INFO - Dependencies all met for dep_context=requeueable deps ti=<TaskInstance: first_dag.first_task scheduled__2023-05-11T00:00:00+00:00 [queued]>
[2023-06-09T16:13:08.753+0000] {taskinstance.py:1308} INFO - Starting attempt 3 of 6
[2023-06-09T16:13:08.788+0000] {taskinstance.py:1327} INFO - Executing <Task(BashOperator): first_task> on 2023-05-11 00:00:00+00:00
[2023-06-09T16:13:08.805+0000] {standard_task_runner.py:57} INFO - Started process 1901 to run task
[2023-06-09T16:13:08.810+0000] {standard_task_runner.py:84} INFO - Running: ['***', 'tasks', 'run', 'first_dag', 'first_task', 'scheduled__2023-05-11T00:00:00+00:00', '--job-id', '36', '--raw', '--subdir', 'DAGS_FOLDER/first_dag.py', '--cfg-path', '/tmp/tmpq8tksk8v']
[2023-06-09T16:13:08.815+0000] {standard_task_runner.py:85} INFO - Job 36: Subtask first_task
[2023-06-09T16:13:08.963+0000] {task_command.py:410} INFO - Running <TaskInstance: first_dag.first_task scheduled__2023-05-11T00:00:00+00:00 [running]> on host 93a4f35889be
[2023-06-09T16:13:09.300+0000] {taskinstance.py:1547} INFO - Exporting env vars: AIRFLOW_CTX_DAG_OWNER='madhu' AIRFLOW_CTX_DAG_ID='first_dag' AIRFLOW_CTX_TASK_ID='first_task' AIRFLOW_CTX_EXECUTION_DATE='2023-05-11T00:00:00+00:00' AIRFLOW_CTX_TRY_NUMBER='3' AIRFLOW_CTX_DAG_RUN_ID='scheduled__2023-05-11T00:00:00+00:00'
[2023-06-09T16:13:09.302+0000] {subprocess.py:63} INFO - Tmp dir root location: 
 /tmp
[2023-06-09T16:13:09.314+0000] {subprocess.py:75} INFO - Running command: ['/bin/bash', '-c', 'hello world i am madhu']
[2023-06-09T16:13:09.349+0000] {subprocess.py:86} INFO - Output:
[2023-06-09T16:13:09.355+0000] {subprocess.py:93} INFO - /bin/bash: line 1: hello: command not found
[2023-06-09T16:13:09.356+0000] {subprocess.py:97} INFO - Command exited with return code 127
[2023-06-09T16:13:09.393+0000] {taskinstance.py:1824} ERROR - Task failed with exception
Traceback (most recent call last):
  File "/home/airflow/.local/lib/python3.7/site-packages/airflow/operators/bash.py", line 211, in execute
    f"Bash command failed. The command returned a non-zero exit code {result.exit_code}."
airflow.exceptions.AirflowException: Bash command failed. The command returned a non-zero exit code 127.
[2023-06-09T16:13:09.402+0000] {taskinstance.py:1350} INFO - Marking task as UP_FOR_RETRY. dag_id=first_dag, task_id=first_task, execution_date=20230511T000000, start_date=20230609T161308, end_date=20230609T161309
[2023-06-09T16:13:09.454+0000] {standard_task_runner.py:109} ERROR - Failed to execute job 36 for task first_task (Bash command failed. The command returned a non-zero exit code 127.; 1901)
[2023-06-09T16:13:09.504+0000] {local_task_job_runner.py:225} INFO - Task exited with return code 1
[2023-06-09T16:13:09.576+0000] {taskinstance.py:2651} INFO - 0 downstream tasks scheduled from follow-on schedule check
